<mujoco model="panda">
  <compiler angle="radian" meshdir="/home/basma/multipanda_ws/src/monkey_sim_node/mujoco"/>

  <option timestep="0.001" iterations="50" tolerance="1e-9" solver="Newton" jacobian="dense" cone="pyramidal"/>

  <default>
    <default class="panda">
      <material specular="0.5" shininess="0.25"/>
      <joint armature="0.1" damping="1" axis="0 0 1" limited="true" range="-2.8973 2.8973"/>
      <general ctrllimited="true" forcelimited="true" dyntype="none" biastype="affine"
          ctrlrange="-2.8973 2.8973" forcerange="-87 87"/>
      <default class="finger">
        <joint axis="0 1 0" type="slide" range="0 0.04"/>
      </default>

      <default class="visual">
        <geom type="mesh" contype="0" conaffinity="0" group="2"/>
      </default>
      <default class="collision">
        <geom type="mesh" group="3"/>
        <default class="fingertip_pad_collision_1">
          <geom type="box" size="0.0085 0.004 0.0085" pos="0 0.0055 0.0445"/>
        </default>
        <default class="fingertip_pad_collision_2">
          <geom type="box" size="0.003 0.002 0.003" pos="0.0055 0.002 0.05"/>
        </default>
        <default class="fingertip_pad_collision_3">
          <geom type="box" size="0.003 0.002 0.003" pos="-0.0055 0.002 0.05"/>
        </default>
        <default class="fingertip_pad_collision_4">
          <geom type="box" size="0.003 0.002 0.0035" pos="0.0055 0.002 0.0395"/>
        </default>
        <default class="fingertip_pad_collision_5">
          <geom type="box" size="0.003 0.002 0.0035" pos="-0.0055 0.002 0.0395"/>
        </default>
      </default>
    </default>
  </default>

  <asset>
    <material class="panda" name="white" rgba="1 1 1 1"/>
    <material class="panda" name="off_white" rgba="0.901961 0.921569 0.929412 1"/>
    <material class="panda" name="black" rgba="0.25 0.25 0.25 1"/>
    <material class="panda" name="green" rgba="0 1 0 1"/>
    <material class="panda" name="light_blue" rgba="0.039216 0.541176 0.780392 1"/>


    <mesh name="link0_c" file="link0.stl"/>
    <mesh name="link1_c" file="link1.stl"/>
    <mesh name="link2_c" file="link2.stl"/>
    <mesh name="link3_c" file="link3.stl"/>
    <mesh name="link4_c" file="link4.stl"/>
    <mesh name="link5_c0" file="link5_collision_0.obj"/>
    <mesh name="link5_c1" file="link5_collision_1.obj"/>
    <mesh name="link5_c2" file="link5_collision_2.obj"/>
    <mesh name="link6_c" file="link6.stl"/>
    <mesh name="link7_c" file="link7.stl"/>
    <mesh name="hand_c" file="hand.stl"/>
    <mesh name="palm" file="palm.stl" scale="0.001 0.001 0.001"/>
    <mesh name="new_l1" file="new_l1.stl" scale="0.001 0.001 0.001"/>
    <mesh name="new_l2" file="new_l2.stl" scale="0.001 0.001 0.001"/>
    <mesh name="new_l3" file="new_l3.stl" scale="0.001 0.001 0.001"/>
    <mesh name="new_l4" file="new_l4.stl" scale="0.001 0.001 0.001"/>
    <mesh name="finger_tip" file="finger_tip.stl" scale="0.001 0.001 0.001"/>
    <mesh name="t1_set" file="t1_set.stl" scale="0.001 0.001 0.001"/>
    <mesh name="t2_set" file="t2_set.stl" scale="0.001 0.001 0.001"/>
    <mesh name="t3_set" file="t3_set.stl" scale="0.001 0.001 0.001"/>
    <mesh name="t4_set" file="t4_set.stl" scale="0.001 0.001 0.001"/>
    <mesh name="finger_tip_silicon" file="finger_tip_silicon.stl" scale="0.001 0.001 0.001"/>


    <mesh file="link0_0.obj"/>
    <mesh file="link0_1.obj"/>
    <mesh file="link0_2.obj"/>
    <mesh file="link0_3.obj"/>
    <mesh file="link0_4.obj"/>
    <mesh file="link0_5.obj"/>
    <mesh file="link0_7.obj"/>
    <mesh file="link0_8.obj"/>
    <mesh file="link0_9.obj"/>
    <mesh file="link0_10.obj"/>
    <mesh file="link0_11.obj"/>
    <mesh file="link1.obj"/>
    <mesh file="link2.obj"/>
    <mesh file="link3_0.obj"/>
    <mesh file="link3_1.obj"/>
    <mesh file="link3_2.obj"/>
    <mesh file="link3_3.obj"/>
    <mesh file="link4_0.obj"/>
    <mesh file="link4_1.obj"/>
    <mesh file="link4_2.obj"/>
    <mesh file="link4_3.obj"/>
    <mesh file="link5_0.obj"/>
    <mesh file="link5_1.obj"/>
    <mesh file="link5_2.obj"/>
    <mesh file="link6_0.obj"/>
    <mesh file="link6_1.obj"/>
    <mesh file="link6_2.obj"/>
    <mesh file="link6_3.obj"/>
    <mesh file="link6_4.obj"/>
    <mesh file="link6_5.obj"/>
    <mesh file="link6_6.obj"/>
    <mesh file="link6_7.obj"/>
    <mesh file="link6_8.obj"/>
    <mesh file="link6_9.obj"/>
    <mesh file="link6_10.obj"/>
    <mesh file="link6_11.obj"/>
    <mesh file="link6_12.obj"/>
    <mesh file="link6_13.obj"/>
    <mesh file="link6_14.obj"/>
    <mesh file="link6_15.obj"/>
    <mesh file="link6_16.obj"/>
    <mesh file="link7_0.obj"/>
    <mesh file="link7_1.obj"/>
    <mesh file="link7_2.obj"/>
    <mesh file="link7_3.obj"/>
    <mesh file="link7_4.obj"/>
    <mesh file="link7_5.obj"/>
    <mesh file="link7_6.obj"/>
    <mesh file="link7_7.obj"/>
    <mesh file="hand_0.obj"/>
    <mesh file="hand_1.obj"/>
    <mesh file="hand_2.obj"/>
    <mesh file="hand_3.obj"/>
    <mesh file="hand_4.obj"/>
    <mesh file="finger_0.obj"/>
    <mesh file="finger_1.obj"/>
    
    
  </asset>

  <worldbody>
    <light name="top" pos="0 0 2" mode="trackcom"/>
    <body name="panda_link0" childclass="panda" pos="0 0 1.1" quat="-0.7071068 0.7071068 0 0" gravcomp="1">
      <!-- <body name="panda_link0" childclass="panda" pos="0 0 0" quat="0 0 0 1" gravcomp="1"> -->
      <inertial mass="0.629769" pos="-0.041018 -0.00014 0.049974"
          fullinertia="0.00315 0.00388 0.004285 8.2904e-7 0.00015 8.2299e-6"/>
      <geom mesh="link0_0" material="off_white" class="visual"/>
      <geom mesh="link0_1" material="black" class="visual"/>
      <geom mesh="link0_2" material="off_white" class="visual"/>
      <geom mesh="link0_3" material="black" class="visual"/>
      <geom mesh="link0_4" material="off_white" class="visual"/>
      <geom mesh="link0_5" material="black" class="visual"/>
      <geom mesh="link0_7" material="white" class="visual"/>
      <geom mesh="link0_8" material="white" class="visual"/>
      <geom mesh="link0_9" material="black" class="visual"/>
      <geom mesh="link0_10" material="off_white" class="visual"/>
      <geom mesh="link0_11" material="white" class="visual"/>
      <geom mesh="link0_c" class="collision"/>
      <body name="panda_link1" pos="0 0 0.333" gravcomp="1">
        <site name="panda_joint1_site" pos="0 0.0 0.0" size=".01 .01 .01" type="ellipsoid" rgba=".8 .2 .1 0"/>
        <inertial mass="4.970684" pos="0.003875 0.002081 -0.04762"
            fullinertia="0.70337 0.70661 0.0091170 -0.00013900 0.0067720 0.019169"/>
        <joint name="panda_joint1" range="-2.7437 2.7437" damping="0.0665" frictionloss="0.2450"/>
        <geom material="white" mesh="link1" class="visual"/>
        <geom mesh="link1_c" class="collision"/>
        <body name="panda_link2" quat="1 -1 0 0" gravcomp="1">
          <site name="panda_joint2_site" pos="0 0.0 0.0" size=".01 .01 .01" type="ellipsoid" rgba=".8 .2 .1 0"/>
          <inertial mass="0.646926" pos="-0.003141 -0.02872 0.003495"
              fullinertia="0.0079620 2.8110e-2 2.5995e-2 -3.925e-3 1.0254e-2 7.04e-4"/>
          <joint name="panda_joint2" range="-1.7837 1.7837" damping="0.1987" frictionloss="0.1523"/>
          <geom material="white" mesh="link2" class="visual"/>
          <geom mesh="link2_c" class="collision"/>
          <body name="panda_link3" pos="0 -0.316 0" quat="1 1 0 0" gravcomp="1">
            <site name="panda_joint3_site" pos="0 0.0 0.0" size=".01 .01 .01" type="ellipsoid" rgba=".8 .2 .1 0"/>
            <joint name="panda_joint3" range="-2.9007 2.9007" damping="0.0399" frictionloss="0.1827"/>
            <inertial mass="3.228604" pos="2.7518e-2 3.9252e-2 -6.6502e-2"
                fullinertia="3.7242e-2 3.6155e-2 1.083e-2 -4.761e-3 -1.1396e-2 -1.2805e-2"/>
            <geom mesh="link3_0" material="white" class="visual"/>
            <geom mesh="link3_1" material="white" class="visual"/>
            <geom mesh="link3_2" material="white" class="visual"/>
            <geom mesh="link3_3" material="black" class="visual"/>
            <geom mesh="link3_c" class="collision"/>
            <body name="panda_link4" pos="0.0825 0 0" quat="1 1 0 0" gravcomp="1">
              <site name="panda_joint4_site" pos="0 0.0 0.0" size=".01 .01 .01" type="ellipsoid" rgba=".8 .2 .1 0"/>
              <inertial mass="3.587895" pos="-5.317e-2 1.04419e-1 2.7454e-2"
                  fullinertia="2.5853e-2 1.9552e-2 2.8323e-2 7.796e-3 -1.332e-3 8.641e-3"/>
              <joint name="panda_joint4" range="-3.0421 -0.1518" damping="0.2257" frictionloss="0.3591"/>
              <geom mesh="link4_0" material="white" class="visual"/>
              <geom mesh="link4_1" material="white" class="visual"/>
              <geom mesh="link4_2" material="black" class="visual"/>
              <geom mesh="link4_3" material="white" class="visual"/>
              <geom mesh="link4_c" class="collision"/>
              <body name="panda_link5" pos="-0.0825 0.384 0" quat="1 -1 0 0" gravcomp="1">
                <site name="panda_joint5_site" pos="0 0.0 0.0" size=".01 .01 .01" type="ellipsoid" rgba=".8 .2 .1 0"/>          
                <inertial mass="1.225946" pos="-1.1953e-2 4.1065e-2 -3.8437e-2"
                    fullinertia="3.5549e-2 2.9474e-2 8.627e-3 -2.117e-3 -4.037e-3 2.29e-4"/>
                <joint name="panda_joint5" range="-2.8065 2.8065" damping="0.1023" frictionloss="0.2669"/>
                <geom mesh="link5_0" material="black" class="visual"/>
                <geom mesh="link5_1" material="white" class="visual"/>
                <geom mesh="link5_2" material="white" class="visual"/>
                <geom mesh="link5_c0" class="collision"/>
                <geom mesh="link5_c1" class="collision"/>
                <geom mesh="link5_c2" class="collision"/>
                <body name="panda_link6" quat="1 1 0 0" gravcomp="1">
                  <site name="panda_joint6_site" pos="0 0.0 0.0" size=".01 .01 .01" type="ellipsoid" rgba=".8 .2 .1 0"/>
                  <inertial mass="1.666555" pos="6.0149e-2 -1.4117e-2 -1.0517e-2"
                      fullinertia="1.964e-3 4.354e-3 5.433e-3 1.09e-4 -1.158e-3 3.41e-4"/>
                  <joint name="panda_joint6" range="0.5445 4.5169" damping="-0.0132" frictionloss="0.1658"/>
                  <geom mesh="link6_0" material="off_white" class="visual"/>
                  <geom mesh="link6_1" material="white" class="visual"/>
                  <geom mesh="link6_2" material="black" class="visual"/>
                  <geom mesh="link6_3" material="white" class="visual"/>
                  <geom mesh="link6_4" material="white" class="visual"/>
                  <geom mesh="link6_5" material="white" class="visual"/>
                  <geom mesh="link6_6" material="white" class="visual"/>
                  <geom mesh="link6_7" material="light_blue" class="visual"/>
                  <geom mesh="link6_8" material="light_blue" class="visual"/>
                  <geom mesh="link6_9" material="black" class="visual"/>
                  <geom mesh="link6_10" material="black" class="visual"/>
                  <geom mesh="link6_11" material="white" class="visual"/>
                  <geom mesh="link6_12" material="green" class="visual"/>
                  <geom mesh="link6_13" material="white" class="visual"/>
                  <geom mesh="link6_14" material="black" class="visual"/>
                  <geom mesh="link6_15" material="black" class="visual"/>
                  <geom mesh="link6_16" material="white" class="visual"/>
                  <geom mesh="link6_c" class="collision"/>
                  <body name="panda_link7" pos="0.088 0 0" quat="1 1 0 0" gravcomp="1">
                    <site name="panda_joint7_site" pos="0 0.0 0.0" size=".01 .01 .01" type="ellipsoid" rgba=".8 .2 .1 0"/>
                    <inertial mass="7.35522e-01" pos="1.0517e-2 -4.252e-3 6.1597e-2"
                        fullinertia="1.2516e-2 1.0027e-2 4.815e-3 -4.28e-4 -1.196e-3 -7.41e-4"/>
                    <joint name="panda_joint7" range="-3.0159 3.0159" damping="0.0638" frictionloss="1.2109"/>
                    <geom mesh="link7_0" material="white" class="visual"/>
                    <geom mesh="link7_1" material="black" class="visual"/>
                    <geom mesh="link7_2" material="black" class="visual"/>
                    <geom mesh="link7_3" material="black" class="visual"/>
                    <geom mesh="link7_4" material="black" class="visual"/>
                    <geom mesh="link7_5" material="black" class="visual"/>
                    <geom mesh="link7_6" material="black" class="visual"/>
                    <geom mesh="link7_7" material="white" class="visual"/>
                    <geom mesh="link7_c" class="collision"/>
                    <body name="panda_link8" pos="0 -0.01 0.209" gravcomp="1">
                      <site name="panda_ee_site" pos="0 0 0" size=".01 .01 .01" type="ellipsoid" rgba=".8 .2 .1 0"/>
                      <site name="panda_flange_site" pos="0 0 0" size=".01 .01 .01" type="ellipsoid" rgba=".8 .2 .1 0"/>
                      <body name="dummy_panda_gripper" pos="0 0 0" gravcomp="0">
                        <inertial mass="1e-8" pos="0 0 0" diaginertia="1e-8 1e-8 1e-8"/>
                        <joint name="panda_finger_joint1" pos="0 0 0" axis="0 1 0" range="0 0.00000001" damping="0.1" frictionloss="0.0"/>
                        <body name="dummy_panda_finger2" pos="0 0 0">
                          <inertial mass="1e-8" pos="0 0 0" diaginertia="1e-8 1e-8 1e-8"/>
                          <joint name="panda_finger_joint2" pos="0 0 0" axis="0 1 0" range="0 0.000001" damping="0.1" frictionloss="0.0"/>
                        </body>
                      </body>
                      <body name="allegro_hand" quat="0.9238795 0 0 -0.3826834" gravcomp="1">
                        <geom pos="0.02 0 -0.1" quat="0.000563312 -0.706825 0.707388 0.000562864" type="mesh" rgba="0.2 0.2 0.2 1" mesh="palm"/>

                        <!-- Link 0_0 - Finger link -->
                        <body name="link_0_0" pos="0.0005 0.0425 -0.005" quat="0.999048 -0.0436194 0 0">
                          <inertial pos="0 0 0" quat="0.99546 0.00522746 -0.091558 0.0254773" mass="0.0176" diaginertia="1.32064e-05 1.22498e-05 2.64678e-06"/>
                          <joint name="joint_0_0" pos="0 0 0" axis="0 0 1" range="-0.3 0.3" actuatorfrcrange="-15 15" damping="3" frictionloss="10"/>
                          <geom pos="-0.0625 -0.022 0.167" quat="0.707388 0 0 -0.706825" type="mesh" rgba="0.2 0.2 0.2 1" mesh="new_l1"/>
                          <body name="link_1_0" pos="0 0 0.017">
                            <inertial pos="0 0 0" quat="0.0215631 0.648029 -0.0176964 0.761105" mass="0.086" diaginertia="5.66968e-05 4.87935e-05 1.75097e-05"/>
                            <joint name="joint_1_0" pos="0 0 0" axis="0 1 0" range="-0.01 1.6" actuatorfrcrange="-15 15" damping="3" frictionloss="5"/>
                            <geom pos="-0.0625 -0.022 0.1495" quat="0.707388 0 0 -0.706825" type="mesh" rgba="0.2 0.2 0.2 1" mesh="new_l2"/>
                            <body name="link_2_0" pos="0 0 0.0431">
                              <inertial pos="0 0 0" quat="0.522066 0.476389 0.468158 0.530405" mass="0.0367" diaginertia="1.45504e-05 1.30076e-05 3.70193e-06"/>
                              <joint name="joint_2_0" pos="0 0 0" axis="0 1 0" range="-0.07 1.86" actuatorfrcrange="-15 15" damping="8" frictionloss="10"/>
                              <geom pos="-0.0625 -0.022 0.1065" quat="0.707388 0 0 -0.706825" type="mesh" rgba="0.2 0.2 0.2 1" mesh="new_l3"/>
                              <body name="link_3_0" pos="0 0 0.038">
                                <inertial pos="0 0 0.0119298" quat="0.708568 0 0 0.705642" mass="0.0057" diaginertia="5.27679e-06 4.04675e-06 2.638e-06"/>
                                <joint name="joint_3_0" pos="0 0 0" axis="0 1 0" range="-0.02 2.01" actuatorfrcrange="-15 15" damping="10" frictionloss="12"/>
                                <geom pos="-0.0625 -0.022 0.0685" quat="0.707388 0 0 -0.706825" type="mesh" rgba="0.2 0.2 0.2 1" mesh="new_l4"/>
                                <geom pos="-0.05482 -0.01493 0.02205" quat="0.707388 0 0 -0.706825" type="mesh" rgba="0.9 0.9 0.9 1" mesh="finger_tip"/>
                              </body>
                            </body>
                          </body>
                        </body>

                        <!-- Link 4_0 - Another finger link -->
                        <body name="link_4_0" pos="0 0 -0.002">
                          <inertial pos="0 0 0" quat="0.99546 0.00522746 -0.091558 0.0254773" mass="0.0176" diaginertia="1.32064e-05 1.22498e-05 2.64678e-06"/>
                          <joint name="joint_4_0" pos="0 0 0" axis="0 0 1" range="-0.26 0.26" actuatorfrcrange="-15 15" damping="3" frictionloss="10"/>
                          <geom pos="-0.0625 -0.022 0.167" quat="0.707388 0 0 -0.706825" type="mesh" rgba="0.2 0.2 0.2 1" mesh="new_l1"/>
                          <body name="link_5_0" pos="0 0 0.017">
                            <inertial pos="0 0 0" quat="0.0215631 0.648029 -0.0176964 0.761105" mass="0.086" diaginertia="5.66968e-05 4.87935e-05 1.75097e-05"/>
                            <joint name="joint_5_0" pos="0 0 0" axis="0 1 0" range="-0.21 1.79" actuatorfrcrange="-15 15" damping="3" frictionloss="5"/>
                            <geom pos="-0.0625 -0.022 0.1495" quat="0.707388 0 0 -0.706825" type="mesh" rgba="0.2 0.2 0.2 1" mesh="new_l2"/>
                            <body name="link_6_0" pos="0 0 0.0431">
                              <inertial pos="0 0 0" quat="0.522066 0.476389 0.468158 0.530405" mass="0.0367" diaginertia="1.45504e-05 1.30076e-05 3.70193e-06"/>
                              <joint name="joint_6_0" pos="0 0 0" axis="0 1 0" range="-0.12 1.86" actuatorfrcrange="-15 15" damping="8" frictionloss="10"/>
                              <geom pos="-0.0625 -0.022 0.1065" quat="0.707388 0 0 -0.706825" type="mesh" rgba="0.2 0.2 0.2 1" mesh="new_l3"/>
                              <body name="link_7_0" pos="0 0 0.038">
                                <inertial pos="0 0 0.0119298" quat="0.708568 0 0 0.705642" mass="0.0057" diaginertia="5.27679e-06 4.04675e-06 2.638e-06"/>
                                <joint name="joint_7_0" pos="0 0 0" axis="0 1 0" range="-0.21 1.85" actuatorfrcrange="-15 15" damping="10" frictionloss="12"/>
                                <geom pos="-0.0625 -0.022 0.0685" quat="0.707388 0 0 -0.706825" type="mesh" rgba="0.2 0.2 0.2 1" mesh="new_l4"/>
                                <geom pos="-0.05482 -0.01493 0.02205" quat="0.707388 0 0 -0.706825" type="mesh" rgba="0.9 0.9 0.9 1" mesh="finger_tip"/>
                              </body>
                            </body>
                          </body>
                        </body>

                        <!-- Link 8_0 - Another finger link -->
                        <body name="link_8_0" pos="0.0005 -0.0425 -0.005" quat="0.999048 0.0436194 0 0">
                          <inertial pos="0 0 0" quat="0.99546 0.00522746 -0.091558 0.0254773" mass="0.0176" diaginertia="1.32064e-05 1.22498e-05 2.64678e-06"/>
                          <joint name="joint_8_0" pos="0 0 0" axis="0 0 1" range="-0.26 0.29" actuatorfrcrange="-15 15" damping="3" frictionloss="10"/>
                          <geom pos="-0.0625 -0.022 0.167" quat="0.707388 0 0 -0.706825" type="mesh" rgba="0.2 0.2 0.2 1" mesh="new_l1"/>
                          <body name="link_9_0" pos="0 0 0.017">
                            <inertial pos="0 0 0" quat="0.0215631 0.648029 -0.0176964 0.761105" mass="0.086" diaginertia="5.66968e-05 4.87935e-05 1.75097e-05"/>
                            <joint name="joint_9_0" pos="0 0 0" axis="0 1 0" range="-0.21 1.79" actuatorfrcrange="-15 15" damping="3" frictionloss="5"/>
                            <geom pos="-0.0625 -0.022 0.1495" quat="0.707388 0 0 -0.706825" type="mesh" rgba="0.2 0.2 0.2 1" mesh="new_l2"/>
                            <body name="link_10_0" pos="0 0 0.0431">
                              <inertial pos="0 0 0" quat="0.522066 0.476389 0.468158 0.530405" mass="0.0367" diaginertia="1.45504e-05 1.30076e-05 3.70193e-06"/>
                              <joint name="joint_10_0" pos="0 0 0" axis="0 1 0" range="-0.12 1.86" actuatorfrcrange="-15 15" damping="8" frictionloss="10"/>
                              <geom pos="-0.0625 -0.022 0.1065" quat="0.707388 0 0 -0.706825" type="mesh" rgba="0.2 0.2 0.2 1" mesh="new_l3"/>
                              <body name="link_11_0" pos="0 0 0.038">
                                <inertial pos="0 0 0.0119298" quat="0.708568 0 0 0.705642" mass="0.0057" diaginertia="5.27679e-06 4.04675e-06 2.638e-06"/>
                                <joint name="joint_11_0" pos="0 0 0" axis="0 1 0" range="-0.21 1.85" actuatorfrcrange="-15 15" damping="10" frictionloss="12"/>
                                <geom pos="-0.0625 -0.022 0.0685" quat="0.707388 0 0 -0.706825" type="mesh" rgba="0.2 0.2 0.2 1" mesh="new_l4"/>
                                <geom pos="-0.05482 -0.01493 0.02205" quat="0.707388 0 0 -0.706825" type="mesh" rgba="0.9 0.9 0.9 1" mesh="finger_tip"/>
                              </body>
                            </body>
                          </body>
                        </body>

                        <!-- Link 12_0 - Using t4 -->
                        <body name="link_12_0" pos="0.002 0.027 -0.06342" quat="0.477714 -0.521334 -0.521334 -0.477714">
                          <inertial pos="0 0 0" quat="0.790345 0.612646 0.00415506 0.00170531" mass="0.0446" diaginertia="5.44036e-05 5.07545e-05 6.43189e-06"/>
                          <joint name="joint_12_0" pos="0 0 0" axis="-1 0 0" range="0 1.78" actuatorfrcrange="-15 15" damping="3" frictionloss="10"/>
                          <geom pos="0.021 -0.1145 0.0725" quat="0.923879 0.382684 0.000430969 -0.00104045" type="mesh" rgba="0.2 0.2 0.2 1" mesh="t1_set"/>
                          <body name="link_13_0" pos="-0.001 0 0.06874">
                            <inertial pos="0 0 0" quat="0.99567 -0.0927403 -5.38842e-05 -0.00629079" mass="0.0173" diaginertia="1.52002e-05 1.37061e-05 2.46665e-06"/>
                            <joint name="joint_13_0" pos="0 0 0" axis="0 0 1" range="-0.26 1.65" actuatorfrcrange="-15 15" damping="3" frictionloss="5"/>
                            <geom pos="-0.138 -0.0605 0.2143" quat="0.706825 4.48402e-07 0.00112618 -0.707387" type="mesh" rgba="0.2 0.2 0.2 1" mesh="t2_set"/>
                            <body name="link_14_0">
                              <inertial pos="0 0 0" quat="0.491771 0.51789 0.513259 0.475937" mass="0.03607" diaginertia="1.54053e-05 1.39209e-05 3.65383e-06"/>
                              <joint name="joint_14_0" pos="0 0 0" axis="0 1 0" range="-0.05 1.85" actuatorfrcrange="-15 15" damping="3" frictionloss="10"/>
                              <geom pos="-0.1265 -0.061 0.166" quat="0.706825 4.48402e-07 0.00112618 -0.707387" type="mesh" rgba="0.2 0.2 0.2 1" mesh="t3_set"/>
                              <body name="link_15_0" pos="0 0 0.038">
                                <inertial pos="0 0 0.00201149" quat="0.48443 0.52214 0.517609 0.474107" mass="0.0348" diaginertia="1.56292e-05 1.15965e-05 7.23667e-06"/>
                                <joint name="joint_15_0" pos="0 0 0" axis="0 1 0" range="-0.09 1.8" actuatorfrcrange="-15 15" damping="3" frictionloss="12"/>
                                <geom pos="-0.149 -0.061 0.096" quat="0.706825 4.48402e-07 0.00112618 -0.707387" type="mesh" rgba="0.2 0.2 0.2 1" mesh="t4_set"/>
                                <geom pos="-0.014 0.0545 0.0328" quat="0.000796327 0 0 1" type="mesh" rgba="0.9 0.9 0.9 1" mesh="finger_tip_silicon"/>
                              </body>
                            </body>
                          </body>
                        </body>
                      </body>  
                    </body>
                  </body>
                </body>
              </body>
            </body>
          </body>
        </body>
      </body>
    </body>
  </worldbody>

  <contact>
    <exclude body1="panda_link7" body2="panda_link8"/>
  </contact>


  <tendon>
    <fixed name="split">
      <joint joint="panda_finger_joint1" coef="0.5"/>
      <joint joint="panda_finger_joint2" coef="0.5"/>
    </fixed>
  </tendon>

  <actuator>
    <motor name="panda_act_trq1" joint="panda_joint1" ctrlrange="-87 87" ctrllimited="true"/>
    <motor name="panda_act_trq2" joint="panda_joint2" ctrlrange="-87 87" ctrllimited="true"/>
    <motor name="panda_act_trq3" joint="panda_joint3" ctrlrange="-87 87" ctrllimited="true"/>
    <motor name="panda_act_trq4" joint="panda_joint4" ctrlrange="-87 87" ctrllimited="true"/>
    <motor name="panda_act_trq5" joint="panda_joint5" ctrlrange="-12 12" ctrllimited="true"/>
    <motor name="panda_act_trq6" joint="panda_joint6" ctrlrange="-12 12" ctrllimited="true"/>
    <motor name="panda_act_trq7" joint="panda_joint7" ctrlrange="-12 12" ctrllimited="true"/>

    <position name="panda_act_pos1" joint="panda_joint1" kp="10" kv="1"/>
    <position name="panda_act_pos2" joint="panda_joint2" kp="10" kv="1"/>
    <position name="panda_act_pos3" joint="panda_joint3" kp="10" kv="1"/>
    <position name="panda_act_pos4" joint="panda_joint4" kp="10" kv="1"/>
    <position name="panda_act_pos5" joint="panda_joint5" kp="10" kv="1"/>
    <position name="panda_act_pos6" joint="panda_joint6" kp="10" kv="1"/>
    <position name="panda_act_pos7" joint="panda_joint7" kp="10" kv="1"/>

    <velocity name="panda_act_vel1" joint="panda_joint1" kv="1"/>
    <velocity name="panda_act_vel2" joint="panda_joint2" kv="1"/>
    <velocity name="panda_act_vel3" joint="panda_joint3" kv="1"/>
    <velocity name="panda_act_vel4" joint="panda_joint4" kv="1"/>
    <velocity name="panda_act_vel5" joint="panda_joint5" kv="1"/>
    <velocity name="panda_act_vel6" joint="panda_joint6" kv="1"/>
    <velocity name="panda_act_vel7" joint="panda_joint7" kv="1"/>
    
    <position name="allegro_act_joint_0_0" joint="joint_0_0" kp="10" kv="1"/>
    <position name="allegro_act_joint_1_0" joint="joint_1_0" kp="10" kv="1"/>
    <position name="allegro_act_joint_2_0" joint="joint_2_0" kp="10" kv="1"/>
    <position name="allegro_act_joint_3_0" joint="joint_3_0" kp="10" kv="1"/>
    <position name="allegro_act_joint_4_0" joint="joint_4_0" kp="10" kv="1"/>
    <position name="allegro_act_joint_5_0" joint="joint_5_0" kp="10" kv="1"/>
    <position name="allegro_act_joint_6_0" joint="joint_6_0" kp="10" kv="1"/>
    <position name="allegro_act_joint_7_0" joint="joint_7_0" kp="10" kv="1"/>
    <position name="allegro_act_joint_8_0" joint="joint_8_0" kp="10" kv="1"/>
    <position name="allegro_act_joint_9_0" joint="joint_9_0" kp="10" kv="1"/>
    <position name="allegro_act_joint_10_0" joint="joint_10_0" kp="10" kv="1"/>
    <position name="allegro_act_joint_11_0" joint="joint_11_0" kp="10" kv="1"/>
    <position name="allegro_act_joint_12_0" joint="joint_12_0" kp="10" kv="1"/>
    <position name="allegro_act_joint_13_0" joint="joint_13_0" kp="10" kv="1"/>
    <position name="allegro_act_joint_14_0" joint="joint_14_0" kp="10" kv="1"/>
    <position name="allegro_act_joint_15_0" joint="joint_15_0" kp="10" kv="1"/>
    <general class="panda" name="panda_act_gripper" tendon="split" forcerange="0 0.00000001" ctrlrange="0 1" gainprm="0.01568627451 0 0" biasprm="0 -100 -10"/>

  </actuator>


</mujoco>
